Workbook

Sheet YTD ummary
B2: NOIR Cinemas - Unaizah
B3: Managed & Operated by - Mukta A2 Cinemas
B5: Cinema | D5: Noir Cinema | K5: Financial | L5: 2026 - 27
B6: Location | D6: Unaizah | K6: VAT | L6: 0.15
B7: Screens | D7: 4 | K7: GCAM | L7: 0.1
B8: Seats | D8: 238
B10: Month | C10: Admits | D10: ATP | E10: OCC% | F10: GBO Rev | G10: G-Conc Rev | H10: SPH | I10: ASR | J10: Conversion | K10: COGS % | L10: Total Revenue
B11: YTD | C11: =C26 -> 23849 | D11: =+D26 -> 31.123242 | E11: =E26 -> 0 | F11: =+F26 -> 742258.2 | G11: =+G26 -> 375587.7 | H11: =+H26 -> 15.748572 | I11: =I26 -> 0 | J11: =J26 -> 0 | K11: =K26 -> 0 | L11: =+L26 -> 1117845.9
B12: Budgeted | C12: 31000 | D12: - | E12: - | F12: 1038500 | G12: 744000 | H12: - | I12: - | J12: - | K12: - | L12: =F12+G12 -> 1782500
B13: Achived % | C13: =C11/C12 -> 0.76932258 | D13: - | E13: - | F13: =F11/F12 -> 0.71474068 | G13: =G11/G12 -> 0.50482218 | H13: =H11/H12 -> #VALUE! | I13: - | J13: - | K13: - | L13: =L11/L12 -> 0.62712252
B14: 46023 | C14: ='Jan 2026'!G44 -> 1265 | D14: ='Jan 2026'!I44 -> 33.501976 | E14: ='Jan 2026'!J44 -> 0.038119632 | F14: ='Jan 2026'!H44 -> 42380 | G14: ='Jan 2026'!P44 -> 22104 | H14: ='Jan 2026'!Q44 -> 17.473518 | I14: ='Jan 2026'!S44 -> 0.52964427 | J14: ='Jan 2026'!W44 -> 1.1272727 | K14: ='Jan 2026'!Y44 -> 0.19954216 | L14: =F14+G14 -> 64484
B15: 46054 | C15: ='Feb 2026'!G41 -> 462 | D15: ='Feb 2026'!I41 -> 27.277056 | E15: ='Feb 2026'!J41 -> 0.021174206 | F15: ='Feb 2026'!H41 -> 12602 | G15: ='Feb 2026'!P41 -> 12145.78 | H15: ='Feb 2026'!Q41 -> 26.289567 | I15: ='Feb 2026'!S41 -> 0.80519481 | J15: ='Feb 2026'!W41 -> 1.538961 | K15: ='Feb 2026'!Y41 -> 0.19152907 | L15: =F15+G15 -> 24747.78
B16: 46082 | C16: ='Mar2026'!G44 -> 3809 | D16: ='Mar2026'!I44 -> 33.756367 | E16: ='Mar2026'!J44 -> 0.15543132 | F16: ='Mar2026'!H44 -> 128578 | G16: ='Mar2026'!P44 -> 68528 | H16: ='Mar2026'!Q44 -> 17.991074 | I16: ='Mar2026'!S44 -> 0.40535574 | J16: ='Mar2026'!W44 -> 0.93279076 | K16: ='Mar2026'!Y44 -> 0.18068235 | L16: =F16+G16 -> 197106
B17: 46113 | C17: ='Apr2026'!G44 -> 3689 | D17: ='Apr2026'!I44 -> 33.479751 | E17: ='Apr2026'!J44 -> 0.10655998 | F17: ='Apr2026'!H44 -> 123506.8 | G17: ='Apr2026'!P44 -> 50049.53 | H17: ='Apr2026'!Q44 -> 13.567235 | I17: ='Apr2026'!S44 -> 0.32176742 | J17: ='Apr2026'!W44 -> 0.70777989 | K17: ='Apr2026'!Y44 -> 0.17203418 | L17: =F17+G17 -> 173556.33
B18: 46143 | C18: ='May 2026'!G44 -> 4122 | D18: ='May 2026'!I44 -> 33.41853 | E18: ='May 2026'!J44 -> 0.12690496 | F18: ='May 2026'!H44 -> 137751.18 | G18: ='May 2026'!P44 -> 53778.71 | H18: ='May 2026'!Q44 -> 13.046752 | I18: ='May 2026'!S44 -> 0.33357593 | J18: ='May 2026'!W44 -> 0.63731198 | K18: ='May 2026'!Y44 -> 0.19948452 | L18: =F18+G18 -> 191529.89
B19: 46174 | C19: ='Jun 2026'!G44 -> 1990 | D19: ='Jun 2026'!I44 -> 26.338693 | E19: ='Jun 2026'!J44 -> 0.059757965 | F19: ='Jun 2026'!H44 -> 52414 | G19: ='Jun 2026'!P44 -> 36984.27 | H19: ='Jun 2026'!Q44 -> 18.58506 | I19: ='Jun 2026'!S44 -> 0.43567839 | J19: ='Jun 2026'!W44 -> 0.90552764 | K19: ='Jun 2026'!Y44 -> 0.19599954 | L19: =F19+G19 -> 89398.27
B20: 46204 | C20: ='Jul 2026'!G44 -> 2303 | D20: ='Jul 2026'!I44 -> 22.201259 | E20: ='Jul 2026'!J44 -> 0.065398268 | F20: ='Jul 2026'!H44 -> 51129.5 | G20: ='Jul 2026'!P44 -> 46102.47 | H20: ='Jul 2026'!Q44 -> 20.018441 | I20: ='Jul 2026'!S44 -> 0.44767694 | J20: ='Jul 2026'!W44 -> 0.93617021 | K20: ='Jul 2026'!Y44 -> 0.19380176 | L20: =F20+G20 -> 97231.97
B21: 46235 | C21: ='Aug 2026'!G44 -> 4624 | D21: ='Aug 2026'!I44 -> 30.719446 | E21: ='Aug 2026'!J44 -> 0.138813 | F21: ='Aug 2026'!H44 -> 142046.72 | G21: ='Aug 2026'!P44 -> 60976.94 | H21: ='Aug 2026'!Q44 -> 13.187054 | I21: ='Aug 2026'!S44 -> 0.3300173 | J21: ='Aug 2026'!W44 -> 0.57266436 | K21: ='Aug 2026'!Y44 -> 0.18643868 | L21: =F21+G21 -> 203023.66
B22: 46266 | C22: ='Sep 2026'!G43 -> 1491 | D22: ='Sep 2026'!I43 -> 32.279007 | E22: ='Sep 2026'!J43 -> 0.046242595 | F22: ='Sep 2026'!H43 -> 48128 | G22: ='Sep 2026'!P43 -> 22398 | H22: ='Sep 2026'!Q43 -> 15.022133 | I22: ='Sep 2026'!S43 -> 0.38564722 | J22: ='Sep 2026'!W43 -> 0.64185111 | K22: ='Sep 2026'!Y43 -> 0.16997678 | L22: =F22+G22 -> 70526
B23: 46296 | C23: ='Oct 2026'!G44 -> 94 | D23: ='Oct 2026'!I44 -> 39.595745 | E23: ='Oct 2026'!J44 -> 0.04752275 | F23: ='Oct 2026'!H44 -> 3722 | G23: ='Oct 2026'!P44 -> 2520 | H23: ='Oct 2026'!Q44 -> 26.808511 | I23: ='Oct 2026'!S44 -> 0.63829787 | J23: ='Oct 2026'!W44 -> 1.2765957 | K23: ='Oct 2026'!Y44 -> 0.16684921 | L23: =F23+G23 -> 6242
B24: 46327 | C24: 0 | D24: 0 | E24: ='MTD Summary'!E55 -> 0 | F24: 0 | G24: 0 | H24: 0 | I24: 0 | J24: 0 | K24: 0 | L24: =F24+G24 -> 0
B25: 46357 | C25: 0 | D25: 0 | E25: ='MTD Summary'!E56 -> 0 | F25: 0 | G25: 0 | H25: 0 | I25: 0 | J25: 0 | K25: 0 | L25: =F25+G25 -> 0
B26: TOTAL | C26: =SUM(C14:C25) -> 23849 | D26: =F26/C26 -> 31.123242 | E26: ='MTD Summary'!E44 -> 0 | F26: =SUM(F14:F25) -> 742258.2 | G26: =SUM(G14:G25) -> 375587.7 | H26: =G26/C26 -> 15.748572 | I26: ='MTD Summary'!I44 -> 0 | J26: ='MTD Summary'!J44 -> 0 | K26: ='MTD Summary'!K44 -> 0 | L26: =SUM(L14:L25) -> 1117845.9

Sheet MTD Summary
B2: NOIR Cinemas -Unaizah
B3: Managed & Operated by - Mukta A2 Cinemas
B5: Cinema | D5: Noir Cinema | K5: Month | L5: 46296
B6: Location | D6: Unaizah | K6: Financial | L6: 2026
B7: Screens | D7: 4 | K7: VAT | L7: 0.15
B8: Seats | D8: 238 | K8: GCAM | L8: 0.1
B10: Date | C10: Admits | D10: ATP | E10: OCC% | F10: GBO Rev | G10: G-Conc Rev | H10: SPH | I10: ASR | J10: Conversion | K10: COGS % | L10: Total Revenue
B11: MTD | C11: =C44 -> 0 | D11: =D44 -> 0 | E11: =E44 -> 0 | F11: =F44 -> 0 | G11: =G44 -> 0 | H11: =H44 -> 0 | I11: =I44 -> 0 | J11: =J44 -> 0 | ... L11: =L44 -> 0
B12: Budgeted | C12: 0 | D12: - | E12: - | F12: 0 | G12: 0 | H12: - | I12: - | J12: - | K12: - | L12: =F12+G12 -> 0
B13: Achieved % | C13: =C11/C12 -> #DIV/0! | D13: - | E13: - | F13: =F11/F12 -> #DIV/0! | G13: =G11/G12 -> #DIV/0! | H13: - | I13: - | J13: - | K13: - | L13: =L11/L12 -> #DIV/0!
B14: 46296 | C14: ='Oct 2026'!G13 -> 55 | D14: ='Oct 2026'!H13 -> 2180 | E14: ='Oct 2026'!I13 -> 39.636364 | F14: ='Oct 2026'!J13 -> 0.055611729 | G14: ='Oct 2026'!K13 -> 284.34783 | H14: ='Oct 2026'!L13 -> 1895.6522 | I14: ='Oct 2026'!M13 -> 176.33 | J14: ='Oct 2026'!N13 -> 1719.3222 | ... L14: ='Oct 2026'!P13 -> 1277
B15: 46297 | C15: ='Oct 2026'!G14 -> 39 | D15: ='Oct 2026'!H14 -> 1542 | E15: ='Oct 2026'!I14 -> 39.538462 | F15: ='Oct 2026'!J14 -> 0.039433771 | G15: ='Oct 2026'!K14 -> 201.13043 | H15: ='Oct 2026'!L14 -> 1340.8696 | I15: ='Oct 2026'!M14 -> 95.99 | J15: ='Oct 2026'!N14 -> 1244.8796 | ... L15: ='Oct 2026'!P14 -> 1243
B16: 46298 | C16: ='Oct 2026'!G15 -> 0 | D16: ='Oct 2026'!H15 -> 0 | E16: ='Oct 2026'!I15 -> 0 | F16: ='Oct 2026'!J15 -> 0 | G16: ='Oct 2026'!K15 -> 0 | H16: ='Oct 2026'!L15 -> 0 | I16: ='Oct 2026'!M15 -> 0 | J16: ='Oct 2026'!N15 -> 0 | ... L16: ='Oct 2026'!P15 -> 0
B17: 46299 | C17: ='Oct 2026'!G16 -> 0 | D17: ='Oct 2026'!H16 -> 0 | E17: ='Oct 2026'!I16 -> 0 | F17: ='Oct 2026'!J16 -> 0 | G17: ='Oct 2026'!K16 -> 0 | H17: ='Oct 2026'!L16 -> 0 | I17: ='Oct 2026'!M16 -> 0 | J17: ='Oct 2026'!N16 -> 0 | ... L17: ='Oct 2026'!P16 -> 0
B18: 46300 | C18: ='Oct 2026'!G17 -> 0 | D18: ='Oct 2026'!H17 -> 0 | E18: ='Oct 2026'!I17 -> 0 | F18: ='Oct 2026'!J17 -> 0 | G18: ='Oct 2026'!K17 -> 0 | H18: ='Oct 2026'!L17 -> 0 | I18: ='Oct 2026'!M17 -> 0 | J18: ='Oct 2026'!N17 -> 0 | ... L18: ='Oct 2026'!P17 -> 0
B19: 46301 | C19: ='Oct 2026'!G18 -> 0 | D19: ='Oct 2026'!H18 -> 0 | E19: ='Oct 2026'!I18 -> 0 | F19: ='Oct 2026'!J18 -> 0 | G19: ='Oct 2026'!K18 -> 0 | H19: ='Oct 2026'!L18 -> 0 | I19: ='Oct 2026'!M18 -> 0 | J19: ='Oct 2026'!N18 -> 0 | ... L19: ='Oct 2026'!P18 -> 0
B20: 46302 | C20: ='Oct 2026'!G19 -> 0 | D20: ='Oct 2026'!H19 -> 0 | E20: ='Oct 2026'!I19 -> 0 | F20: ='Oct 2026'!J19 -> 0 | G20: ='Oct 2026'!K19 -> 0 | H20: ='Oct 2026'!L19 -> 0 | I20: ='Oct 2026'!M19 -> 0 | J20: ='Oct 2026'!N19 -> 0 | ... L20: ='Oct 2026'!P19 -> 0
B21: 46303 | C21: ='Oct 2026'!G20 -> 0 | D21: ='Oct 2026'!H20 -> 0 | E21: ='Oct 2026'!I20 -> 0 | F21: ='Oct 2026'!J20 -> 0 | G21: ='Oct 2026'!K20 -> 0 | H21: ='Oct 2026'!L20 -> 0 | I21: ='Oct 2026'!M20 -> 0 | J21: ='Oct 2026'!N20 -> 0 | ... L21: ='Oct 2026'!P20 -> 0
B22: 46304 | C22: ='Oct 2026'!G21 -> 0 | D22: ='Oct 2026'!H21 -> 0 | E22: ='Oct 2026'!I21 -> 0 | F22: ='Oct 2026'!J21 -> 0 | G22: ='Oct 2026'!K21 -> 0 | H22: ='Oct 2026'!L21 -> 0 | I22: ='Oct 2026'!M21 -> 0 | J22: ='Oct 2026'!N21 -> 0 | ... L22: ='Oct 2026'!P21 -> 0
B23: 46305 | C23: ='Oct 2026'!G22 -> 0 | D23: ='Oct 2026'!H22 -> 0 | E23: ='Oct 2026'!I22 -> 0 | F23: ='Oct 2026'!J22 -> 0 | G23: ='Oct 2026'!K22 -> 0 | H23: ='Oct 2026'!L22 -> 0 | I23: ='Oct 2026'!M22 -> 0 | J23: ='Oct 2026'!N22 -> 0 | ... L23: ='Oct 2026'!P22 -> 0
B24: 46306 | C24: ='Oct 2026'!G23 -> 0 | D24: ='Oct 2026'!H23 -> 0 | E24: ='Oct 2026'!I23 -> 0 | F24: ='Oct 2026'!J23 -> 0 | G24: ='Oct 2026'!K23 -> 0 | H24: ='Oct 2026'!L23 -> 0 | I24: ='Oct 2026'!M23 -> 0 | J24: ='Oct 2026'!N23 -> 0 | ... L24: ='Oct 2026'!P23 -> 0
B25: 46307 | C25: ='Oct 2026'!G24 -> 0 | D25: ='Oct 2026'!H24 -> 0 | E25: ='Oct 2026'!I24 -> 0 | F25: ='Oct 2026'!J24 -> 0 | G25: ='Oct 2026'!K24 -> 0 | H25: ='Oct 2026'!L24 -> 0 | I25: ='Oct 2026'!M24 -> 0 | J25: ='Oct 2026'!N24 -> 0 | ... L25: ='Oct 2026'!P24 -> 0
... B43: 46325 | C43: ='Oct 2026'!G42 -> 0 | D43: ='Oct 2026'!H42 -> 0 | E43: ='Oct 2026'!I42 -> 0 | F43: ='Oct 2026'!J42 -> 0 | G43: ='Oct 2026'!K42 -> 0 | H43: ='Oct 2026'!L42 -> 0 | I43: ='Oct 2026'!M42 -> 0 | J43: ='Oct 2026'!N42 -> 0 | ... L43: ='Oct 2026'!P42 -> 0
B44: 46326 | C44: 0 | D44: 0 | E44: 0 | F44: 0 | H44: 0 | I44: 0 | J44: 0 | K44: 0 | L44: 0

Sheet Jan 2026
B2: NOIR Cinemas - Unaizah
B3: Managed & Operated by - Mukta A2 Cinemas
B5: Cinema | D5: Noir Cinema | G5: Month | I5: 46023
B6: Location | D6: Unizah | G6: Financial Year | I6: 2026
B7: Screens | D7: 4 | G7: VAT | I7: 0.15
B8: Seats | D8: 238 | G8: GCAM | I8: 0.1
G10: Box Office | P10: Concession | AA10: Total Box Office Revenue | AC10: Total Concession Revenue | AE10: Grand Total Revenue
B11: Date | C11: Day | D11: Seats | E11: Total Shows | F11: Total Available Capacity | G11: Admits | H11: Box Office Revenue | I11: ATP | J11: Occ % | K11: VAT (15%) | L11: Net BO Rev Before GCAM | M11: GCAM | N11: Net BO Rev After GCAM | P11: Concession Rev | Q11: SPH | R11: Transaction | S11: ASR | T11: VAT | U11: Net Concession Revenue | V11: Items Sold | W11: Concession Conversion % | X11: Concessions Standard Cost | Y11: COGS | AA11: Gross | AB11: Nett | AC11: Gross | AD11: Nett | AE11: Gross | AF11: Nett
B12: TOTAL MTD | D12: =D44 -> 238 | E12: =E44 -> 562 | F12: =F44 -> 33185 | G12: =G44 -> 1265 | H12: =H44 -> 42380 | I12: =I44 -> 33.501976 | J12: =J44 -> 0.038119632 | K12: =K44 -> 5527.8261 | ... N12: =N44 -> 33473.044 | P12: =P44 -> 22104 | Q12: =Q44 -> 17.473518 | R12: =R44 -> 670 | S12: =S44 -> 0.52964427 | T12: =T44 -> 2883.1304 | U12: =U44 -> 19220.87 | V12: =V44 -> 1426 | W12: =W44 -> 1.1272727 | ... Y12: =Y44 -> 0.19954216 | AA12: =AA44 -> 42380 | AB12: =AB44 -> 33473.044 | AC12: =AC44 -> 22104 | AD12: =AD44 -> 19220.87 | AE12: =AE44 -> 64484 | AF12: =AF44 -> 52693.913
B13: 46023 | C13: Thursday | D13: 238 | E13: 17 | F13: 1016 | G13: 90 | H13: 3010 | I13: =H13/G13 -> 33.444444 | J13: =G13/F13 -> 0.088582677 | K13: =H13*15/115 -> 392.6087 | L13: =H13-K13 -> 2617.3913 | M13: 231.15 | N13: =L13-M13 -> 2386.2413 | P13: 1203 | Q13: =P13/G13 -> 13.366667 | R13: 33 | S13: =(R13/G13) -> 0.36666667 | T13: =P13*15/115 -> 156.91304 | U13: =P13-T13 -> 1046.087 | V13: 61 | W13: =V13/G13 -> 0.67777778 | X13: 252.53 | Y13: =(X13/P13) -> 0.20991687 | AA13: =H13 -> 3010 | AB13: =N13 -> 2386.2413 | AC13: =P13 -> 1203 | AD13: =U13 -> 1046.087 | AE13: =AA13+AC13 -> 4213 | AF13: =AB13+AD13 -> 3432.3283 | AG13: `
B14: 46024 | C14: Friday | D14: 238 | E14: 17 | F14: 1016 | G14: 63 | H14: 2146 | I14: =H14/G14 -> 34.063492 | J14: =G14/F14 -> 0.062007874 | K14: =H14*15/115 -> 279.91304 | L14: =H14-K14 -> 1866.087 | M14: 181.06 | N14: =L14-M14 -> 1685.027 | P14: 948 | Q14: =P14/G14 -> 15.047619 | R14: 27 | S14: =(R14/G14) -> 0.42857143 | T14: =P14*15/115 -> 123.65217 | U14: =P14-T14 -> 824.34783 | V14: 55 | W14: =V14/G14 -> 0.87301587 | X14: 174.62 | Y14: =(X14/P14) -> 0.18419831 | AA14: =H14 -> 2146 | AB14: =N14 -> 1685.027 | AC14: =P14 -> 948 | AD14: =U14 -> 824.34783 | AE14: =AA14+AC14 -> 3094 | AF14: =AB14+AD14 -> 2509.3748
B15: 46025 | C15: Saturday | D15: 238 | E15: 17 | F15: 1016 | G15: 31 | H15: 992 | I15: =H15/G15 -> 32 | J15: =G15/F15 -> 0.030511811 | K15: =H15*15/115 -> 129.3913 | L15: =H15-K15 -> 862.6087 | M15: 86.27 | N15: =L15-M15 -> 776.3387 | P15: 374 | Q15: =P15/G15 -> 12.064516 | R15: 12 | S15: =(R15/G15) -> 0.38709677 | T15: =P15*15/115 -> 48.782609 | U15: =P15-T15 -> 325.21739 | V15: 22 | W15: =V15/G15 -> 0.70967742 | X15: 64.26 | Y15: =(X15/P15) -> 0.17181818 | AA15: =H15 -> 992 | AB15: =N15 -> 776.3387 | AC15: =P15 -> 374 | AD15: =U15 -> 325.21739 | AE15: =AA15+AC15 -> 1366 | AF15: =AB15+AD15 -> 1101.5561
B16: 46026 | C16: Sunday | D16: 238 | E16: 17 | F16: 1016 | G16: 17 | H16: 594 | I16: =H16/G16 -> 34.941176 | J16: =G16/F16 -> 0.016732283 | K16: =H16*15/115 -> 77.478261 | L16: =H16-K16 -> 516.52174 | M16: 43.31 | N16: =L16-M16 -> 473.21174 | P16: 573 | Q16: =P16/G16 -> 33.705882 | R16: 11 | S16: =(R16/G16) -> 0.64705882 | T16: =P16*15/115 -> 74.73913 | U16: =P16-T16 -> 498.26087 | V16: 29 | W16: =V16/G16 -> 1.7058824 | X16: 120.05 | Y16: =(X16/P16) -> 0.20951134 | AA16: =H16 -> 594 | AB16: =N16 -> 473.21174 | AC16: =P16 -> 573 | AD16: =U16 -> 498.26087 | AE16: =AA16+AC16 -> 1167 | AF16: =AB16+AD16 -> 971.47261
B17: 46027 | C17: Monday | D17: 238 | E17: 17 | F17: 1016 | G17: 31 | H17: 992 | I17: =H17/G17 -> 32 | J17: =G17/F17 -> 0.030511811 | K17: =H17*15/115 -> 129.3913 | L17: =H17-K17 -> 862.6087 | M17: 80.71 | N17: =L17-M17 -> 781.8987 | P17: 662 | Q17: =P17/G17 -> 21.354839 | R17: 22 | S17: =(R17/G17) -> 0.70967742 | T17: =P17*15/115 -> 86.347826 | U17: =P17-T17 -> 575.65217 | V17: 30 | W17: =V17/G17 -> 0.96774194 | X17: 132.31 | Y17: =(X17/P17) -> 0.19986405 | AA17: =H17 -> 992 | AB17: =N17 -> 781.8987 | AC17: =P17 -> 662 | AD17: =U17 -> 575.65217 | AE17: =AA17+AC17 -> 1654 | AF17: =AB17+AD17 -> 1357.5509
B18: 46028 | C18: Tuesday | D18: 238 | E18: 17 | F18: 1016 | G18: 22 | H18: 724 | I18: =H18/G18 -> 32.909091 | J18: =G18/F18 -> 0.021653543 | K18: =H18*15/115 -> 94.434783 | L18: =H18-K18 -> 629.56522 | M18: 62.96 | N18: =L18-M18 -> 566.60522 | P18: 332 | Q18: =P18/G18 -> 15.090909 | R18: 8 | S18: =(R18/G18) -> 0.36363636 | T18: =P18*15/115 -> 43.304348 | U18: =P18-T18 -> 288.69565 | V18: 19 | W18: =V18/G18 -> 0.86363636 | X18: 79.34 | Y18: =(X18/P18) -> 0.2389759 | AA18: =H18 -> 724 | AB18: =N18 -> 566.60522 | AC18: =P18 -> 332 | AD18: =U18 -> 288.69565 | AE18: =AA18+AC18 -> 1056 | AF18: =AB18+AD18 -> 855.30087
B19: 46029 | C19: Wednesday | D19: 238 | E19: 17 | F19: 1016 | G19: 41 | H19: 1332 | I19: =H19/G19 -> 32.487805 | J19: =G19/F19 -> 0.040354331 | K19: =H19*15/115 -> 173.73913 | L19: =H19-K19 -> 1158.2609 | M19: 88.01 | N19: =L19-M19 -> 1070.2509 | P19: 596 | Q19: =P19/G19 -> 14.536585 | R19: 36 | S19: =(R19/G19) -> 0.87804878 | T19: =P19*15/115 -> 77.73913 | U19: =P19-T19 -> 518.26087 | V19: 78 | W19: =V19/G19 -> 1.902439 | X19: 156.3 | Y19: =(X19/P19) -> 0.26224832 | AA19: =H19 -> 1332 | AB19: =N19 -> 1070.2509 | AC19: =P19 -> 596 | AD19: =U19 -> 518.26087 | AE19: =AA19+AC19 -> 1928 | AF19: =AB19+AD19 -> 1588.5117
B20: 46030 | C20: Thursday | D20: 238 | E20: 20 | F20: 1190 | G20: 58 | H20: 1936 | I20: =H20/G20 -> 33.37931 | J20: =G20/F20 -> 0.048739496 | K20: =H20*15/115 -> 252.52174 | L20: =H20-K20 -> 1683.4783 | M20: 162.8 | N20: =L20-M20 -> 1520.6783 | P20: 1276 | Q20: =P20/G20 -> 22 | R20: 41 | S20: =(R20/G20) -> 0.70689655 | T20: =P20*15/115 -> 166.43478 | U20: =P20-T20 -> 1109.5652 | V20: 70 | W20: =V20/G20 -> 1.2068966 | X20: 218.51 | Y20: =(X20/P20) -> 0.17124608 | AA20: =H20 -> 1936 | AB20: =N20 -> 1520.6783 | AC20: =P20 -> 1276 | AD20: =U20 -> 1109.5652 | AE20: =AA20+AC20 -> 3212 | AF20: =AB20+AD20 -> 2630.2435
B21: 46031 | C21: Friday | D21: 238 | E21: 16 | F21: 952 | G21: 71 | H21: 2382 | I21: =H21/G21 -> 33.549296 | J21: =G21/F21 -> 0.074579832 | K21: =H21*15/115 -> 310.69565 | L21: =H21-K21 -> 2071.3043 | M21: 174.8 | N21: =L21-M21 -> 1896.5043 | P21: 1179 | Q21: =P21/G21 -> 16.605634 | R21: 31 | S21: =(R21/G21) -> 0.43661972 | T21: =P21*15/115 -> 153.78261 | U21: =P21-T21 -> 1025.2174 | V21: 68 | W21: =V21/G21 -> 0.95774648 | X21: 213.65 | Y21: =(X21/P21) -> 0.18121289 | AA21: =H21 -> 2382 | AB21: =N21 -> 1896.5043 | AC21: =P21 -> 1179 | AD21: =U21 -> 1025.2174 | AE21: =AA21+AC21 -> 3561 | AF21: =AB21+AD21 -> 2921.7217
B22: 46032 | C22: Saturday | D22: 238 | E22: 20 | F22: 1190 | G22: 61 | H22: 2002 | I22: =H22/G22 -> 32.819672 | J22: =G22/F22 -> 0.051260504 | K22: =H22*15/115 -> 261.13043 | L22: =H22-K22 -> 1740.8696 | M22: 137.93 | N22: =L22-M22 -> 1602.9396 | P22: 1006 | Q22: =P22/G22 -> 16.491803 | R22: 28 | S22: =(R22/G22) -> 0.45901639 | T22: =P22*15/115 -> 131.21739 | U22: =P22-T22 -> 874.78261 | V22: 65 | W22: =V22/G22 -> 1.0655738 | X22: 196.35 | Y22: =(X22/P22) -> 0.19517893 | AA22: =H22 -> 2002 | AB22: =N22 -> 1602.9396 | AC22: =P22 -> 1006 | AD22: =U22 -> 874.78261 | AE22: =AA22+AC22 -> 3008 | AF22: =AB22+AD22 -> 2477.7222
B23: 46033 | C23: Sunday | D23: 238 | E23: 20 | F23: 1190 | G23: 40 | H23: 1410 | I23: =H23/G23 -> 35.25 | J23: =G23/F23 -> 0.033613445 | K23: =H23*15/115 -> 183.91304 | L23: =H23-K23 -> 1226.087 | M23: 81.22 | N23: =L23-M23 -> 1144.867 | P23: 884 | Q23: =P23/G23 -> 22.1 | R23: 37 | S23: =(R23/G23) -> 0.925 | T23: =P23*15/115 -> 115.30435 | U23: =P23-T23 -> 768.69565 | V23: 75 | W23: =V23/G23 -> 1.875 | X23: 181.39 | Y23: =(X23/P23) -> 0.20519231 | AA23: =H23 -> 1410 | AB23: =N23 -> 1144.867 | AC23: =P23 -> 884 | AD23: =U23 -> 768.69565 | AE23: =AA23+AC23 -> 2294 | AF23: =AB23+AD23 -> 1913.5626
B24: 46034 | C24: Monday | D24: 238 | E24: 20 | F24: 1190 | G24: 33 | H24: 1056 | I24: =H24/G24 -> 32 | J24: =G24/F24 -> 0.027731092 | K24: =H24*15/115 -> 137.73913 | L24: =H24-K24 -> 918.26087 | M24: 58.44 | N24: =L24-M24 -> 859.82087 | P24: 770 | Q24: =P24/G24 -> 23.333333 | R24: 14 | S24: =(R24/G24) -> 0.42424242 | T24: =P24*15/115 -> 100.43478 | U24: =P24-T24 -> 669.56522 | V24: 69 | W24: =V24/G24 -> 2.0909091 | X24: 154.65 | Y24: =(X24/P24) -> 0.20084416 | AA24: =H24 -> 1056 | AB24: =N24 -> 859.82087 | AC24: =P24 -> 770 | AD24: =U24 -> 669.56522 | AE24: =AA24+AC24 -> 1826 | AF24: =AB24+AD24 -> 1529.3861
B25: 46035 | C25: Tuesday | D25: 238 | E25: 20 | F25: 1190 | G25: 23 | H25: 756 | I25: =H25/G25 -> 32.869565 | J25: =G25/F25 -> 0.019327731 | K25: =H25*15/115 -> 98.608696 | L25: =H25-K25 -> 657.3913 | M25: 49.05 | N25: =L25-M25 -> 608.3413 | P25: 1059 | Q25: =P25/G25 -> 46.043478 | R25: 30 | S25: =(R25/G25) -> 1.3043478 | T25: =P25*15/115 -> 138.13043 | U25: =P25-T25 -> 920.86957 | V25: 69 | W25: =V25/G25 -> 3 | X25: 224.45 | Y25: =(X25/P25) -> 0.21194523 | AA25: =H25 -> 756 | AB25: =N25 -> 608.3413 | AC25: =P25 -> 1059 | AD25: =U25 -> 920.86957 | AE25: =AA25+AC25 -> 1815 | AF25: =AB25+AD25 -> 1529.2109
... B32: 46042 | C32: Tuesday | D32: 238 | E32: 18 | F32: 1053 | G32: 18 | H32: 646 | I32: =H32/G32 -> 35.888889 | J32: =G32/F32 -> 0.017094017 | K32: =H32*15/115 -> 84.26087 | L32: =H32-K32 -> 561.73913 | M32: 56.18 | N32: =L32-M32 -> 505.55913 | P32: 620 | Q32: =P32/G32 -> 34.444444 | R32: 17 | S32: =(R32/G32) -> 0.94444444 | T32: =P32*15/115 -> 80.869565 | U32: =P32-T32 -> 539.13043 | V32: 34 | W32: =V32/G32 -> 1.8888889 | X32: 120.55 | Y32: =(X32/P32) -> 0.19443548 | AA32: =H32 -> 646 | AB32: =N32 -> 505.55913 | AC32: =P32 -> 620 | AD32: =U32 -> 539.13043 | AE32: =AA32+AC32 -> 1266 | AF32: =AB32+AD32 -> 1044.6896
B33: 46043 | C33: Wednesday | D33: 238 | E33: 18 | F33: 1053 | G33: 17 | H33: 544 | I33: =H33/G33 -> 32 | J33: =G33/F33 -> 0.016144349 | K33: =H33*15/115 -> 70.956522 | L33: =H33-K33 -> 473.04348 | M33: 41.75 | N33: =L33-M33 -> 431.29348 | P33: 218 | Q33: 18.76 | R33: 11 | S33: =(R33/G33) -> 0.64705882 | T33: =P33*15/115 -> 28.434783 | U33: =P33-T33 -> 189.56522 | V33: 30 | W33: =V33/G33 -> 1.7647059 | X33: 65.56 | Y33: =(X33/P33) -> 0.30073394 | AA33: =H33 -> 544 | AB33: =N33 -> 431.29348 | AC33: =P33 -> 218 | AD33: =U33 -> 189.56522 | AE33: =AA33+AC33 -> 762 | AF33: =AB33+AD33 -> 620.8587
B34: 46044 | C34: Thursday | D34: 238 | E34: 18 | F34: 1030 | G34: 104 | H34: 3538 | I34: =H34/G34 -> 34.019231 | J34: =G34/F34 -> 0.10097087 | K34: =H34*15/115 -> 461.47826 | L34: =H34-K34 -> 3076.5217 | M34: 302.11 | N34: =L34-M34 -> 2774.4117 | P34: 1157 | Q34: =P34/G34 -> 11.125 | R34: 30 | S34: =(R34/G34) -> 0.28846154 | T34: =P34*15/115 -> 150.91304 | U34: =P34-T34 -> 1006.087 | V34: 67 | W34: =V34/G34 -> 0.64423077 | X34: 217.08 | Y34: =(X34/P34) -> 0.18762316 | AA34: =H34 -> 3538 | AB34: =N34 -> 2774.4117 | AC34: =P34 -> 1157 | AD34: =U34 -> 1006.087 | AE34: =AA34+AC34 -> 4695 | AF34: =AB34+AD34 -> 3780.4987
B35: 46045 | C35: Friday | D35: 238 | E35: 19 | F35: 1110 | G35: 94 | H35: 3278 | I35: =H35/G35 -> 34.87234 | J35: =G35/F35 -> 0.084684685 | K35: =H35*15/115 -> 427.56522 | L35: =H35-K35 -> 2850.4348 | M35: 285.06 | N35: =L35-M35 -> 2565.3748 | P35: 721 | Q35: =P35/G35 -> 7.6702128 | R35: 25 | S35: =(R35/G35) -> 0.26595745 | T35: =P35*15/115 -> 94.043478 | U35: =P35-T35 -> 626.95652 | V35: 46 | W35: =V35/G35 -> 0.4893617 | X35: 119.83 | Y35: =(X35/P35) -> 0.16619972 | AA35: =H35 -> 3278 | AB35: =N35 -> 2565.3748 | AC35: =P35 -> 721 | AD35: =U35 -> 626.95652 | AE35: =AA35+AC35 -> 3999 | AF35: =AB35+AD35 -> 3192.3313
B36: 46046 | C36: Saturday | D36: 238 | E36: 19 | F36: 1110 | G36: 48 | H36: 1556 | I36: =H36/G36 -> 32.416667 | J36: =G36/F36 -> 0.043243243 | K36: =H36*15/115 -> 202.95652 | L36: =H36-K36 -> 1353.0435 | M36: 132.54 | N36: =L36-M36 -> 1220.5035 | P36: 611 | Q36: =P36/G36 -> 12.729167 | R36: 19 | S36: =(R36/G36) -> 0.39583333 | T36: =P36*15/115 -> 79.695652 | U36: =P36-T36 -> 531.30435 | V36: 36 | W36: =V36/G36 -> 0.75 | X36: 121.25 | Y36: =(X36/P36) -> 0.19844517 | AA36: =H36 -> 1556 | AB36: =N36 -> 1220.5035 | AC36: =P36 -> 611 | AD36: =U36 -> 531.30435 | AE36: =AA36+AC36 -> 2167 | AF36: =AB36+AD36 -> 1751.8078
B37: 46047 | C37: Sunday | D37: 238 | E37: 19 | F37: 1110 | G37: 12 | H37: 424 | I37: =H37/G37 -> 35.333333 | J37: =G37/F37 -> 0.010810811 | K37: =H37*15/115 -> 55.304348 | L37: =H37-K37 -> 368.69565 | M37: 36.87 | N37: =L37-M37 -> 331.82565 | P37: 423 | Q37: =P37/G37 -> 35.25 | R37: 8 | S37: =(R37/G37) -> 0.66666667 | T37: =P37*15/115 -> 55.173913 | U37: =P37-T37 -> 367.82609 | V37: 24 | W37: =V37/G37 -> 2 | X37: 76.8 | Y37: =(X37/P37) -> 0.18156028 | AA37: =H37 -> 424 | AB37: =N37 -> 331.82565 | AC37: =P37 -> 423 | AD37: =U37 -> 367.82609 | AE37: =AA37+AC37 -> 847 | AF37: =AB37+AD37 -> 699.65174
B38: 46048 | C38: Monday | D38: 238 | E38: 19 | F38: 1110 | G38: 23 | H38: 736 | I38: =H38/G38 -> 32 | J38: =G38/F38 -> 0.020720721 | K38: =H38*15/115 -> 96 | L38: =H38-K38 -> 640 | M38: 64.01 | N38: =L38-M38 -> 575.99 | P38: 225 | Q38: =P38/G38 -> 9.7826087 | R38: 8 | S38: =(R38/G38) -> 0.34782609 | T38: =P38*15/115 -> 29.347826 | U38: =P38-T38 -> 195.65217 | V38: 12 | W38: =V38/G38 -> 0.52173913 | X38: 50.06 | Y38: =(X38/P38) -> 0.22248889 | AA38: =H38 -> 736 | AB38: =N38 -> 575.99 | AC38: =P38 -> 225 | AD38: =U38 -> 195.65217 | AE38: =AA38+AC38 -> 961 | AF38: =AB38+AD38 -> 771.64217
B39: 46049 | C39: Tuesday | D39: 238 | E39: 19 | F39: 1110 | G39: 10 | H39: 330 | I39: =H39/G39 -> 33 | J39: =G39/F39 -> 0.009009009 | K39: =H39*15/115 -> 43.043478 | L39: =H39-K39 -> 286.95652 | M39: 28.7 | N39: =L39-M39 -> 258.25652 | P39: 354 | Q39: =P39/G39 -> 35.4 | R39: 13 | S39: =(R39/G39) -> 1.3 | T39: =P39*15/115 -> 46.173913 | U39: =P39-T39 -> 307.82609 | V39: 19 | W39: =V39/G39 -> 1.9 | X39: 55.37 | Y39: =(X39/P39) -> 0.15641243 | AA39: =H39 -> 330 | AB39: =N39 -> 258.25652 | AC39: =P39 -> 354 | AD39: =U39 -> 307.82609 | AE39: =AA39+AC39 -> 684 | AF39: =AB39+AD39 -> 566.08261
B40: 46050 | C40: Wednesday | D40: 238 | E40: 19 | F40: 1110 | G40: 21 | H40: 702 | I40: =H40/G40 -> 33.428571 | J40: =G40/F40 -> 0.018918919 | K40: =H40*15/115 -> 91.565217 | L40: =H40-K40 -> 610.43478 | M40: 61.05 | N40: =L40-M40 -> 549.38478 | P40: 471 | Q40: =P40/G40 -> 22.428571 | R40: 17 | S40: =(R40/G40) -> 0.80952381 | T40: =P40*15/115 -> 61.434783 | U40: =P40-T40 -> 409.56522 | V40: 24 | W40: =V40/G40 -> 1.1428571 | X40: 86.21 | Y40: =(X40/P40) -> 0.18303609 | AA40: =H40 -> 702 | AB40: =N40 -> 549.38478 | AC40: =P40 -> 471 | AD40: =U40 -> 409.56522 | AE40: =AA40+AC40 -> 1173 | AF40: =AB40+AD40 -> 958.95
B41: 46051 | C41: Thursday | D41: 238 | E41: 17 | F41: 1016 | G41: 54 | H41: 1738 | I41: =H41/G41 -> 32.185185 | J41: =G41/F41 -> 0.053149606 | K41: =H41*15/115 -> 226.69565 | L41: =H41-K41 -> 1511.3043 | M41: 151.15 | N41: =L41-M41 -> 1360.1543 | P41: 867 | Q41: =P41/G41 -> 16.055556 | R41: 27 | S41: =(R41/G41) -> 0.5 | T41: =P41*15/115 -> 113.08696 | U41: =P41-T41 -> 753.91304 | V41: 46 | W41: =V41/G41 -> 0.85185185 | X41: 169.88 | Y41: =(X41/P41) -> 0.19594002 | AA41: =H41 -> 1738 | AB41: =N41 -> 1360.1543 | AC41: =P41 -> 867 | AD41: =U41 -> 753.91304 | AE41: =AA41+AC41 -> 2605 | AF41: =AB41+AD41 -> 2114.0674
B42: 46052 | C42: Friday | D42: 238 | E42: 16 | F42: 952 | G42: 82 | H42: 2714 | I42: =H42/G42 -> 33.097561 | J42: =G42/F42 -> 0.086134454 | K42: =H42*15/115 -> 354 | L42: =H42-K42 -> 2360 | M42: 236.03 | N42: =L42-M42 -> 2123.97 | P42: 1059 | Q42: =P42/G42 -> 12.914634 | R42: 32 | S42: =(R42/G42) -> 0.3902439 | T42: =P42*15/115 -> 138.13043 | U42: =P42-T42 -> 920.86957 | V42: 52 | W42: =V42/G42 -> 0.63414634 | X42: 199.54 | Y42: =(X42/P42) -> 0.18842304 | AA42: =H42 -> 2714 | AB42: =N42 -> 2123.97 | AC42: =P42 -> 1059 | AD42: =U42 -> 920.86957 | AE42: =AA42+AC42 -> 3773 | AF42: =AB42+AD42 -> 3044.8396
B43: 46053 | C43: Saturday | D43: 238 | E43: 16 | F43: 952 | G43: 29 | H43: 1058 | I43: =H43/G43 -> 36.482759 | J43: =G43/F43 -> 0.030462185 | K43: =H43*15/115 -> 138 | L43: =H43-K43 -> 920 | M43: 92.02 | N43: =L43-M43 -> 827.98 | P43: 780 | Q43: =P43/G43 -> 26.896552 | R43: 21 | S43: =(R43/G43) -> 0.72413793 | T43: =P43*15/115 -> 101.73913 | U43: =P43-T43 -> 678.26087 | V43: 45 | W43: =V43/G43 -> 1.5517241 | X43: 137.91 | Y43: =(X43/P43) -> 0.17680769 | AA43: =H43 -> 1058 | AB43: =N43 -> 827.98 | AC43: =P43 -> 780 | AD43: =U43 -> 678.26087 | AE43: =AA43+AC43 -> 1838 | AF43: =AB43+AD43 -> 1506.2409
B44: TOTAL | D44: =AVERAGE(D13:D43) -> 238 | E44: =SUM(E13:E43) -> 562 | F44: =SUM(F13:F43) -> 33185 | G44: =SUM(G13:G43) -> 1265 | H44: =SUM(H13:H43) -> 42380 | I44: =H44/G44 -> 33.501976 | J44: =(G44/F44) -> 0.038119632 | K44: =SUM(K13:K43) -> 5527.8261 | L44: =SUM(L13:L43) -> 36852.174 | M44: =SUM(M13:M43) -> 3379.13 | N44: =SUM(N13:N43) -> 33473.044 | P44: =SUM(P13:P43) -> 22104 | Q44: =P44/G44 -> 17.473518 | R44: =SUM(R13:R43) -> 670 | S44: =(R44/G44) -> 0.52964427 | T44: =SUM(T13:T43) -> 2883.1304 | U44: =SUM(U13:U43) -> 19220.87 | V44: =SUM(V13:V43) -> 1426 | W44: =V44/G44 -> 1.1272727 | X44: =SUM(X13:X43) -> 4410.68 | Y44: =(X44/P44) -> 0.19954216 | AA44: =SUM(AA13:AA43) -> 42380 | AB44: =SUM(AB13:AB43) -> 33473.044 | AC44: =SUM(AC13:AC43) -> 22104 | AD44: =SUM(AD13:AD43) -> 19220.87 | AE44: =SUM(AE13:AE43) -> 64484 | AF44: =SUM(AF13:AF43) -> 52693.913

Sheet Feb 2026
B2: NOIR Cinemas - Unaizah
B3: Managed & Operated by - Mukta A2 Cinemas
B5: Cinema | D5: Noir Cinema | G5: Month | I5: 46054
B6: Location | D6: Unizah | G6: Financial Year | I6: 2026
B7: Screens | D7: 4 | G7: VAT | I7: 0.15
B8: Seats | D8: 238 | G8: GCAM | I8: 0.1
G10: Box Office | P10: Concession | AA10: Total Box Office Revenue | AC10: Total Concession Revenue | AE10: Grand Total Revenue
B11: Date | C11: Day | D11: Seats | E11: Total Shows | F11: Total Available Capacity | G11: Admits | H11: Box Office Revenue | I11: ATP | J11: Occ % | K11: VAT (15%) | L11: Net BO Rev Before GCAM | M11: GCAM | N11: Net BO Rev After GCAM | P11: Concession Rev | Q11: SPH | R11: Transaction | S11: ASR | T11: VAT | U11: Net Concession Revenue | V11: Items Sold | W11: Concession Conversion % | X11: Concessions Standard Cost | Y11: COGS | AA11: Gross | AB11: Nett | AC11: Gross | AD11: Nett | AE11: Gross | AF11: Nett
B12: TOTAL MTD | D12: =D41 -> 238 | E12: =E41 -> 367 | F12: =F41 -> 21819 | G12: =G41 -> 462 | H12: =H41 -> 12602 | I12: =I41 -> 27.277056 | J12: =J41 -> 0.021174206 | K12: =K41 -> 1643.7391 | ... N12: =N41 -> 9862.3509 | P12: =P41 -> 12145.78 | Q12: =Q41 -> 26.289567 | R12: =R41 -> 372 | S12: =S41 -> 0.80519481 | T12: =T41 -> 1584.2322 | U12: =U41 -> 10561.548 | V12: =V41 -> 711 | W12: =W41 -> 1.538961 | ... Y12: =Y41 -> 0.19152907 | AA12: =AA41 -> 12602 | AB12: =AB41 -> 9862.3509 | AC12: =AC41 -> 12145.78 | AD12: =AD41 -> 10561.548 | AE12: =AE41 -> 24747.78 | AF12: =AF41 -> 20423.899
B13: 46054 | C13: Sunday | D13: 238 | E13: 16 | F13: 952 | G13: 24 | H13: 768 | I13: =H13/G13 -> 32 | J13: =G13/F13 -> 0.025210084 | K13: =H13*15/115 -> 100.17391 | L13: =H13-K13 -> 667.82609 | M13: 66.79 | N13: =L13-M13 -> 601.03609 | P13: 474 | Q13: =P13/G13 -> 19.75 | R13: 17 | S13: =(R13/G13) -> 0.70833333 | T13: =P13*15/115 -> 61.826087 | U13: =P13-T13 -> 412.17391 | V13: 25 | W13: =V13/G13 -> 1.0416667 | X13: 116 | Y13: =(X13/P13) -> 0.24472574 | AA13: =H13 -> 768 | AB13: =N13 -> 601.03609 | AC13: =P13 -> 474 | AD13: =U13 -> 412.17391 | AE13: =AA13+AC13 -> 1242 | AF13: =AB13+AD13 -> 1013.21
B14: 46055 | C14: Monday | D14: 238 | E14: 16 | F14: 952 | G14: 12 | H14: 384 | I14: =H14/G14 -> 32 | J14: =G14/F14 -> 0.012605042 | K14: =H14*15/115 -> 50.086957 | L14: =H14-K14 -> 333.91304 | M14: 33.4 | N14: =L14-M14 -> 300.51304 | P14: 360 | Q14: =P14/G14 -> 30 | R14: 12 | S14: =(R14/G14) -> 1 | T14: =P14*15/115 -> 46.956522 | U14: =P14-T14 -> 313.04348 | V14: 20 | W14: =V14/G14 -> 1.6666667 | X14: 60.67 | Y14: =(X14/P14) -> 0.16852778 | AA14: =H14 -> 384 | AB14: =N14 -> 300.51304 | AC14: =P14 -> 360 | AD14: =U14 -> 313.04348 | AE14: =AA14+AC14 -> 744 | AF14: =AB14+AD14 -> 613.55652
B15: 46056 | C15: Tuesday | D15: 238 | E15: 16 | F15: 952 | G15: 17 | H15: 564 | I15: =H15/G15 -> 33.176471 | J15: =G15/F15 -> 0.017857143 | K15: =H15*15/115 -> 73.565217 | L15: =H15-K15 -> 490.43478 | M15: 49.05 | N15: =L15-M15 -> 441.38478 | P15: 349 | Q15: =P15/G15 -> 20.529412 | R15: 13 | S15: =(R15/G15) -> 0.76470588 | T15: =P15*15/115 -> 45.521739 | U15: =P15-T15 -> 303.47826 | V15: 22 | W15: =V15/G15 -> 1.2941176 | X15: 68.19 | Y15: =(X15/P15) -> 0.19538682 | AA15: =H15 -> 564 | AB15: =N15 -> 441.38478 | AC15: =P15 -> 349 | AD15: =U15 -> 303.47826 | AE15: =AA15+AC15 -> 913 | AF15: =AB15+AD15 -> 744.86304
B16: 46057 | C16: Wednesday | D16: 238 | E16: 16 | F16: 952 | G16: 13 | H16: 446 | I16: =H16/G16 -> 34.307692 | J16: =G16/F16 -> 0.013655462 | K16: =H16*15/115 -> 58.173913 | L16: =H16-K16 -> 387.82609 | M16: 38.79 | N16: =L16-M16 -> 349.03609 | P16: 243 | Q16: =P16/G16 -> 18.692308 | R16: 9 | S16: =(R16/G16) -> 0.69230769 | T16: =P16*15/115 -> 31.695652 | U16: =P16-T16 -> 211.30435 | V16: 14 | W16: =V16/G16 -> 1.0769231 | X16: 36.45 | Y16: =(X16/P16) -> 0.15 | AA16: =H16 -> 446 | AB16: =N16 -> 349.03609 | AC16: =P16 -> 243 | AD16: =U16 -> 211.30435 | AE16: =AA16+AC16 -> 689 | AF16: =AB16+AD16 -> 560.34043
B17: 46058 | C17: Thursday | D17: 238 | E17: 16 | F17: 952 | G17: 45 | H17: 1020 | I17: =H17/G17 -> 22.666667 | J17: =G17/F17 -> 0.047268908 | K17: =H17*15/115 -> 133.04348 | L17: =H17-K17 -> 886.95652 | M17: 88.7 | N17: =L17-M17 -> 798.25652 | P17: 685 | Q17: =P17/G17 -> 15.222222 | R17: 23 | S17: =(R17/G17) -> 0.51111111 | T17: =P17*15/115 -> 89.347826 | U17: =P17-T17 -> 595.65217 | V17: 44 | W17: =V17/G17 -> 0.97777778 | X17: 135.9 | Y17: =(X17/P17) -> 0.19839416 | AA17: =H17 -> 1020 | AB17: =N17 -> 798.25652 | AC17: =P17 -> 685 | AD17: =U17 -> 595.65217 | AE17: =AA17+AC17 -> 1705 | AF17: =AB17+AD17 -> 1393.9087
B18: 46059 | C18: Friday | D18: 238 | E18: 16 | F18: 952 | G18: 95 | H18: 2090 | I18: =H18/G18 -> 22 | J18: =G18/F18 -> 0.099789916 | K18: =H18*15/115 -> 272.6087 | L18: =H18-K18 -> 1817.3913 | M18: 181.74 | N18: =L18-M18 -> 1635.6513 | P18: 1656 | Q18: =P18/G18 -> 17.431579 | R18: 38 | S18: =(R18/G18) -> 0.4 | T18: =P18*15/115 -> 216 | U18: =P18-T18 -> 1440 | V18: 98 | W18: =V18/G18 -> 1.0315789 | X18: 328.62 | Y18: =(X18/P18) -> 0.19844203 | AA18: =H18 -> 2090 | AB18: =N18 -> 1635.6513 | AC18: =P18 -> 1656 | AD18: =U18 -> 1440 | AE18: =AA18+AC18 -> 3746 | AF18: =AB18+AD18 -> 3075.6513
B19: 46060 | C19: Saturday | D19: 238 | E19: 16 | F19: 952 | G19: 30 | H19: 660 | I19: =H19/G19 -> 22 | J19: =G19/F19 -> 0.031512605 | K19: =H19*15/115 -> 86.086957 | L19: =H19-K19 -> 573.91304 | M19: 57.39 | N19: =L19-M19 -> 516.52304 | P19: 869.78 | Q19: =P19/G19 -> 28.992667 | R19: 22 | S19: =(R19/G19) -> 0.73333333 | T19: =P19*15/115 -> 113.44957 | U19: =P19-T19 -> 756.33043 | V19: 42 | W19: =V19/G19 -> 1.4 | X19: 171.69 | Y19: =(X19/P19) -> 0.19739474 | AA19: =H19 -> 660 | AB19: =N19 -> 516.52304 | AC19: =P19 -> 869.78 | AD19: =U19 -> 756.33043 | AE19: =AA19+AC19 -> 1529.78 | AF19: =AB19+AD19 -> 1272.8535
B20: 46061 | C20: Sunday | D20: 238 | E20: 16 | F20: 952 | G20: 20 | H20: 400 | I20: =H20/G20 -> 20 | J20: =G20/F20 -> 0.021008403 | K20: =H20*15/115 -> 52.173913 | L20: =H20-K20 -> 347.82609 | M20: 34.78 | N20: =L20-M20 -> 313.04609 | P20: 300 | Q20: =P20/G20 -> 15 | R20: 8 | S20: =(R20/G20) -> 0.4 | T20: =P20*15/115 -> 39.130435 | U20: =P20-T20 -> 260.86957 | V20: 21 | W20: =V20/G20 -> 1.05 | X20: 63.97 | Y20: =(X20/P20) -> 0.21323333 | AA20: =H20 -> 400 | AB20: =N20 -> 313.04609 | AC20: =P20 -> 300 | AD20: =U20 -> 260.86957 | AE20: =AA20+AC20 -> 700 | AF20: =AB20+AD20 -> 573.91565
B21: 46062 | C21: Monday | D21: 238 | E21: 16 | F21: 952 | G21: 11 | H21: 240 | I21: =H21/G21 -> 21.818182 | J21: =G21/F21 -> 0.011554622 | K21: =H21*15/115 -> 31.304348 | L21: =H21-K21 -> 208.69565 | M21: 20.87 | N21: =L21-M21 -> 187.82565 | P21: 431 | Q21: =P21/G21 -> 39.181818 | R21: 12 | S21: =(R21/G21) -> 1.0909091 | T21: =P21*15/115 -> 56.217391 | U21: =P21-T21 -> 374.78261 | V21: 26 | W21: =V21/G21 -> 2.3636364 | X21: 67.82 | Y21: =(X21/P21) -> 0.15735499 | AA21: =H21 -> 240 | AB21: =N21 -> 187.82565 | AC21: =P21 -> 431 | AD21: =U21 -> 374.78261 | AE21: =AA21+AC21 -> 671 | AF21: =AB21+AD21 -> 562.60826
B22: 46063 | C22: Tuesday | D22: 238 | E22: 16 | F22: 952 | G22: 24 | H22: 520 | I22: =H22/G22 -> 21.666667 | J22: =G22/F22 -> 0.025210084 | K22: =H22*15/115 -> 67.826087 | L22: =H22-K22 -> 452.17391 | M22: 45.22 | N22: =L22-M22 -> 406.95391 | P22: 721 | Q22: =P22/G22 -> 30.041667 | R22: 18 | S22: =(R22/G22) -> 0.75 | T22: =P22*15/115 -> 94.043478 | U22: =P22-T22 -> 626.95652 | V22: 44 | W22: =V22/G22 -> 1.8333333 | X22: 140.86 | Y22: =(X22/P22) -> 0.19536755 | AA22: =H22 -> 520 | AB22: =N22 -> 406.95391 | AC22: =P22 -> 721 | AD22: =U22 -> 626.95652 | AE22: =AA22+AC22 -> 1241 | AF22: =AB22+AD22 -> 1033.9104
B23: 46064 | C23: Wednesday | D23: 238 | E23: 16 | F23: 952 | G23: 11 | H23: 220 | I23: =H23/G23 -> 20 | J23: =G23/F23 -> 0.011554622 | K23: =H23*15/115 -> 28.695652 | L23: =H23-K23 -> 191.30435 | M23: 19.13 | N23: =L23-M23 -> 172.17435 | P23: 367 | Q23: =P23/G23 -> 33.363636 | R23: 12 | S23: =(R23/G23) -> 1.0909091 | T23: =P23*15/115 -> 47.869565 | U23: =P23-T23 -> 319.13043 | V23: 25 | W23: =V23/G23 -> 2.2727273 | X23: 66.06 | Y23: =(X23/P23) -> 0.18 | AA23: =H23 -> 220 | AB23: =N23 -> 172.17435 | AC23: =P23 -> 367 | AD23: =U23 -> 319.13043 | AE23: =AA23+AC23 -> 587 | AF23: =AB23+AD23 -> 491.30478
B24: 46065 | C24: Thursday | D24: 238 | E24: 16 | F24: 952 | G24: 34 | H24: 1108 | I24: =H24/G24 -> 32.588235 | J24: =G24/F24 -> 0.035714286 | K24: =H24*15/115 -> 144.52174 | L24: =H24-K24 -> 963.47826 | M24: 96.36 | N24: =L24-M24 -> 867.11826 | P24: 946 | Q24: =P24/G24 -> 27.823529 | R24: 25 | S24: =(R24/G24) -> 0.73529412 | T24: =P24*15/115 -> 123.3913 | U24: =P24-T24 -> 822.6087 | V24: 54 | W24: =V24/G24 -> 1.5882353 | X24: 183.37 | Y24: =(X24/P24) -> 0.19383721 | AA24: =H24 -> 1108 | AB24: =N24 -> 867.11826 | AC24: =P24 -> 946 | AD24: =U24 -> 822.6087 | AE24: =AA24+AC24 -> 2054 | AF24: =AB24+AD24 -> 1689.727
... B40: 46081 | C40: Saturday | D40: 238 | E40: 8 | F40: 476 | G40: 0 | H40: 0 | I40: =H40/G40 -> #DIV/0! | J40: =G40/F40 -> 0 | K40: =H40*15/115 -> 0 | L40: =H40-K40 -> 0 | M40: 0 | N40: =L40-M40 -> 0 | P40: 164 | Q40: =P40/G40 -> #DIV/0! | R40: 5 | S40: =(R40/G40) -> #DIV/0! | T40: =P40*15/115 -> 21.391304 | U40: =P40-T40 -> 142.6087 | V40: 10 | W40: =V40/G40 -> #DIV/0! | X40: 34.52 | Y40: =(X40/P40) -> 0.2104878 | AA40: =H40 -> 0 | AB40: =N40 -> 0 | AC40: =P40 -> 164 | AD40: =U40 -> 142.6087 | AE40: =AA40+AC40 -> 164 | AF40: =AB40+AD40 -> 142.6087
B41: TOTAL | D41: =AVERAGE(D13:D40) -> 238 | E41: =SUM(E13:E40) -> 367 | F41: =SUM(F13:F40) -> 21819 | G41: =SUM(G13:G40) -> 462 | H41: =SUM(H13:H40) -> 12602 | I41: =H41/G41 -> 27.277056 | J41: =(G41/F41) -> 0.021174206 | K41: =SUM(K13:K40) -> 1643.7391 | L41: =SUM(L13:L40) -> 10958.261 | M41: =SUM(M13:M40) -> 1095.91 | N41: =SUM(N13:N40) -> 9862.3509 | P41: =SUM(P13:P40) -> 12145.78 | Q41: =P41/G41 -> 26.289567 | R41: =SUM(R13:R40) -> 372 | S41: =(R41/G41) -> 0.80519481 | T41: =SUM(T13:T40) -> 1584.2322 | U41: =SUM(U13:U40) -> 10561.548 | V41: =SUM(V13:V40) -> 711 | W41: =V41/G41 -> 1.538961 | X41: =SUM(X13:X40) -> 2326.27 | Y41: =(X41/P41) -> 0.19152907 | AA41: =SUM(AA13:AA40) -> 12602 | AB41: =SUM(AB13:AB40) -> 9862.3509 | AC41: =SUM(AC13:AC40) -> 12145.78 | AD41: =SUM(AD13:AD40) -> 10561.548 | AE41: =SUM(AE13:AE40) -> 24747.78 | AF41: =SUM(AF13:AF40) -> 20423.899

Sheet Mar2026
B2: NOIR Cinemas - Unaizah
B3: Managed & Operated by - Mukta A2 Cinemas
B5: Cinema | D5: Noir Cinema | G5: Month | I5: 46082
B6: Location | D6: Unizah | G6: Financial Year | I6: 2026
B7: Screens | D7: 4 | G7: VAT | I7: 0.15
B8: Seats | D8: 238 | G8: GCAM | I8: 0.1
G10: Box Office | P10: Concession | AA10: Total Box Office Revenue | AC10: Total Concession Revenue | AE10: Grand Total Revenue
B11: Date | C11: Day | D11: Seats | E11: Total Shows | F11: Total Available Capacity | G11: Admits | H11: Box Office Revenue | I11: ATP | J11: Occ % | K11: VAT (15%) | L11: Net BO Rev Before GCAM | M11: GCAM | N11: Net BO Rev After GCAM | P11: Concession Rev | Q11: SPH | R11: Transaction | S11: ASR | T11: VAT | U11: Net Concession Revenue | V11: Items Sold | W11: Concession Conversion % | X11: Concessions Standard Cost | Y11: COGS | AA11: Gross | AB11: Nett | AC11: Gross | AD11: Nett | AE11: Gross | AF11: Nett
B12: TOTAL MTD | D12: =D44 -> 238 | E12: =E44 -> 411 | F12: =F44 -> 24506 | G12: =G44 -> 3809 | H12: =H44 -> 128578 | I12: =I44 -> 33.756367 | J12: =J44 -> 0.15543132 | K12: =K44 -> 16771.043 | ... N12: =N44 -> 107342.18 | P12: =P44 -> 68528 | Q12: =Q44 -> 17.991074 | R12: =R44 -> 1544 | S12: =S44 -> 0.40535574 | T12: =T44 -> 8938.4348 | U12: =U44 -> 59589.565 | V12: =V44 -> 3553 | W12: =W44 -> 0.93279076 | ... Y12: =Y44 -> 0.18068235 | AA12: =AA44 -> 128578 | AB12: =AB44 -> 107342.18 | AC12: =AC44 -> 68528 | AD12: =AD44 -> 59589.565 | AE12: =AE44 -> 197106 | AF12: =AF44 -> 166931.74
B13: 46082 | C13: Sunday | D13: 238 | E13: 8 | F13: 476 | G13: 6 | H13: 192 | I13: =H13/G13 -> 32 | J13: =G13/F13 -> 0.012605042 | K13: =H13*15/115 -> 25.043478 | L13: =H13-K13 -> 166.95652 | M13: 16.7 | N13: =L13-M13 -> 150.25652 | P13: 466 | Q13: =P13/G13 -> 77.666667 | R13: 17 | S13: =(R13/G13) -> 2.8333333 | T13: =P13*15/115 -> 60.782609 | U13: =P13-T13 -> 405.21739 | V13: 33 | W13: =V13/G13 -> 5.5 | X13: 71.3 | Y13: =(X13/P13) -> 0.15300429 | AA13: =H13 -> 192 | AB13: =N13 -> 150.25652 | AC13: =P13 -> 466 | AD13: =U13 -> 405.21739 | AE13: =AA13+AC13 -> 658 | AF13: =AB13+AD13 -> 555.47391
B14: 46083 | C14: Monday | D14: 238 | E14: 8 | F14: 476 | G14: 2 | H14: 64 | I14: =H14/G14 -> 32 | J14: =G14/F14 -> 0.0042016807 | K14: =H14*15/115 -> 8.3478261 | L14: =H14-K14 -> 55.652174 | M14: 5.57 | N14: =L14-M14 -> 50.082174 | P14: 260 | Q14: =P14/G14 -> 130 | R14: 11 | S14: =(R14/G14) -> 5.5 | T14: =P14*15/115 -> 33.913043 | U14: =P14-T14 -> 226.08696 | V14: 16 | W14: =V14/G14 -> 8 | X14: 47.43 | Y14: =(X14/P14) -> 0.18242308 | AA14: =H14 -> 64 | AB14: =N14 -> 50.082174 | AC14: =P14 -> 260 | AD14: =U14 -> 226.08696 | AE14: =AA14+AC14 -> 324 | AF14: =AB14+AD14 -> 276.16913
B15: 46084 | C15: Saturday | D15: 238 | E15: 8 | F15: 476 | G15: 1 | H15: 32 | I15: =H15/G15 -> 32 | J15: =G15/F15 -> 0.0021008403 | K15: =H15*15/115 -> 4.173913 | L15: =H15-K15 -> 27.826087 | M15: 2.78 | N15: =L15-M15 -> 25.046087 | P15: 443 | Q15: =P15/G15 -> 443 | R15: 18 | S15: =(R15/G15) -> 18 | T15: =P15*15/115 -> 57.782609 | U15: =P15-T15 -> 385.21739 | V15: 34 | W15: =V15/G15 -> 34 | X15: 74.21 | Y15: =(X15/P15) -> 0.16751693 | AA15: =H15 -> 32 | AB15: =N15 -> 25.046087 | AC15: =P15 -> 443 | AD15: =U15 -> 385.21739 | AE15: =AA15+AC15 -> 475 | AF15: =AB15+AD15 -> 410.26348
B16: 46085 | C16: Wednesday | D16: 238 | E16: 8 | F16: 476 | G16: 0 | H16: 0 | I16: =H16/G16 -> #DIV/0! | J16: =G16/F16 -> 0 | K16: =H16*15/115 -> 0 | L16: =H16-K16 -> 0 | M16: 0 | N16: =L16-M16 -> 0 | P16: 750 | Q16: =P16/G16 -> #DIV/0! | R16: 21 | S16: =(R16/G16) -> #DIV/0! | T16: =P16*15/115 -> 97.826087 | U16: =P16-T16 -> 652.17391 | V16: 45 | W16: =V16/G16 -> #DIV/0! | X16: 120.75 | Y16: =(X16/P16) -> 0.161 | AA16: =H16 -> 0 | AB16: =N16 -> 0 | AC16: =P16 -> 750 | AD16: =U16 -> 652.17391 | AE16: =AA16+AC16 -> 750 | AF16: =AB16+AD16 -> 652.17391
B17: 46086 | C17: Thursday | D17: 238 | E17: 8 | F17: 476 | G17: 14 | H17: 448 | I17: =H17/G17 -> 32 | J17: =G17/F17 -> 0.029411765 | K17: =H17*15/115 -> 58.434783 | L17: =H17-K17 -> 389.56522 | M17: 38.96 | N17: =L17-M17 -> 350.60522 | P17: 875 | Q17: =P17/G17 -> 62.5 | R17: 27 | S17: =(R17/G17) -> 1.9285714 | T17: =P17*15/115 -> 114.13043 | U17: =P17-T17 -> 760.86957 | V17: 45 | W17: =V17/G17 -> 3.2142857 | X17: 128.88 | Y17: =(X17/P17) -> 0.14729143 | AA17: =H17 -> 448 | AB17: =N17 -> 350.60522 | AC17: =P17 -> 875 | AD17: =U17 -> 760.86957 | AE17: =AA17+AC17 -> 1323 | AF17: =AB17+AD17 -> 1111.4748
B18: 46087 | C18: Friday | D18: 238 | E18: 8 | F18: 476 | G18: 16 | H18: 532 | I18: =H18/G18 -> 33.25 | J18: =G18/F18 -> 0.033613445 | K18: =H18*15/115 -> 69.391304 | L18: =H18-K18 -> 462.6087 | M18: 46.27 | N18: =L18-M18 -> 416.3387 | P18: 733 | Q18: =P18/G18 -> 45.8125 | R18: 26 | S18: =(R18/G18) -> 1.625 | T18: =P18*15/115 -> 95.608696 | U18: =P18-T18 -> 637.3913 | V18: 41 | W18: =V18/G18 -> 2.5625 | X18: 126.65 | Y18: =(X18/P18) -> 0.17278308 | AA18: =H18 -> 532 | AB18: =N18 -> 416.3387 | AC18: =P18 -> 733 | AD18: =U18 -> 637.3913 | AE18: =AA18+AC18 -> 1265 | AF18: =AB18+AD18 -> 1053.73
B19: 46088 | C19: Saturday | D19: 238 | E19: 8 | F19: 476 | G19: 3 | H19: 126 | I19: =H19/G19 -> 42 | J19: =G19/F19 -> 0.006302521 | K19: =H19*15/115 -> 16.434783 | L19: =H19-K19 -> 109.56522 | M19: 10.96 | N19: =L19-M19 -> 98.605217 | P19: 813 | Q19: =P19/G19 -> 271 | R19: 30 | S19: =(R19/G19) -> 10 | T19: =P19*15/115 -> 106.04348 | U19: =P19-T19 -> 706.95652 | V19: 43 | W19: =V19/G19 -> 14.333333 | X19: 147.94 | Y19: =(X19/P19) -> 0.18196802 | AA19: =H19 -> 126 | AB19: =N19 -> 98.605217 | AC19: =P19 -> 813 | AD19: =U19 -> 706.95652 | AE19: =AA19+AC19 -> 939 | AF19: =AB19+AD19 -> 805.56174
B20: 46089 | C20: Sunday | D20: 238 | E20: 8 | F20: 476 | G20: 1 | H20: 32 | I20: =H20/G20 -> 32 | J20: =G20/F20 -> 0.0021008403 | K20: =H20*15/115 -> 4.173913 | L20: =H20-K20 -> 27.826087 | M20: 2.78 | N20: =L20-M20 -> 25.046087 | P20: 787 | Q20: =P20/G20 -> 787 | R20: 22 | S20: =(R20/G20) -> 22 | T20: =P20*15/115 -> 102.65217 | U20: =P20-T20 -> 684.34783 | V20: 46 | W20: =V20/G20 -> 46 | X20: 144.88 | Y20: =(X20/P20) -> 0.18409149 | AA20: =H20 -> 32 | AB20: =N20 -> 25.046087 | AC20: =P20 -> 787 | AD20: =U20 -> 684.34783 | AE20: =AA20+AC20 -> 819 | AF20: =AB20+AD20 -> 709.39391
B21: 46090 | C21: Monday | D21: 238 | E21: 8 | F21: 476 | G21: 1 | H21: 32 | I21: =H21/G21 -> 32 | J21: =G21/F21 -> 0.0021008403 | K21: =H21*15/115 -> 4.173913 | L21: =H21-K21 -> 27.826087 | M21: 2.78 | N21: =L21-M21 -> 25.046087 | P21: 544 | Q21: =P21/G21 -> 544 | R21: 20 | S21: =(R21/G21) -> 20 | T21: =P21*15/115 -> 70.956522 | U21: =P21-T21 -> 473.04348 | V21: 29 | W21: =V21/G21 -> 29 | X21: 86.5 | Y21: =(X21/P21) -> 0.15900735 | AA21: =H21 -> 32 | AB21: =N21 -> 25.046087 | AC21: =P21 -> 544 | AD21: =U21 -> 473.04348 | AE21: =AA21+AC21 -> 576 | AF21: =AB21+AD21 -> 498.08957
B22: 46091 | C22: Tuesday | D22: 238 | E22: 8 | F22: 476 | G22: 2 | H22: 84 | I22: =H22/G22 -> 42 | J22: =G22/F22 -> 0.0042016807 | K22: =H22*15/115 -> 10.956522 | L22: =H22-K22 -> 73.043478 | M22: 7.3 | N22: =L22-M22 -> 65.743478 | P22: 576 | Q22: =P22/G22 -> 288 | R22: 25 | S22: =(R22/G22) -> 12.5 | T22: =P22*15/115 -> 75.130435 | U22: =P22-T22 -> 500.86957 | V22: 31 | W22: =V22/G22 -> 15.5 | X22: 99.71 | Y22: =(X22/P22) -> 0.17310764 | AA22: =H22 -> 84 | AB22: =N22 -> 65.743478 | AC22: =P22 -> 576 | AD22: =U22 -> 500.86957 | AE22: =AA22+AC22 -> 660 | AF22: =AB22+AD22 -> 566.61304
B23: 46092 | C23: Wednesday | D23: 238 | E23: 8 | F23: 476 | G23: 1 | H23: 32 | I23: =H23/G23 -> 32 | J23: =G23/F23 -> 0.0021008403 | K23: =H23*15/115 -> 4.173913 | L23: =H23-K23 -> 27.826087 | M23: 2.78 | N23: =L23-M23 -> 25.046087 | P23: 362 | Q23: =P23/G23 -> 362 | R23: 14 | S23: =(R23/G23) -> 14 | T23: =P23*15/115 -> 47.217391 | U23: =P23-T23 -> 314.78261 | V23: 23 | W23: =V23/G23 -> 23 | X23: 58.84 | Y23: =(X23/P23) -> 0.16254144 | AA23: =H23 -> 32 | AB23: =N23 -> 25.046087 | AC23: =P23 -> 362 | AD23: =U23 -> 314.78261 | AE23: =AA23+AC23 -> 394 | AF23: =AB23+AD23 -> 339.8287
B24: 46093 | C24: Thursday | D24: 238 | E24: 8 | F24: 476 | G24: 0 | H24: 0 | I24: =H24/G24 -> #DIV/0! | J24: =G24/F24 -> 0 | K24: =H24*15/115 -> 0 | L24: =H24-K24 -> 0 | M24: 0 | N24: =L24-M24 -> 0 | P24: 448 | Q24: =P24/G24 -> #DIV/0! | R24: 18 | S24: =(R24/G24) -> #DIV/0! | T24: =P24*15/115 -> 58.434783 | U24: =P24-T24 -> 389.56522 | V24: 31 | W24: =V24/G24 -> #DIV/0! | X24: 65.9 | Y24: =(X24/P24) -> 0.14709821 | AA24: =H24 -> 0 | AB24: =N24 -> 0 | AC24: =P24 -> 448 | AD24: =U24 -> 389.56522 | AE24: =AA24+AC24 -> 448 | AF24: =AB24+AD24 -> 389.56522
... B43: 46112 | C43: Tuesday | D43: 238 | E43: 16 | F43: 948 | G43: 45 | H43: 1440 | I43: =H43/G43 -> 32 | J43: =G43/F43 -> 0.047468354 | K43: =H43*15/115 -> 187.82609 | L43: =H43-K43 -> 1252.1739 | M43: 47.31 | N43: =L43-M43 -> 1204.8639 | P43: 621 | Q43: =P43/G43 -> 13.8 | R43: 16 | S43: =(R43/G43) -> 0.35555556 | T43: =P43*15/115 -> 81 | U43: =P43-T43 -> 540 | V43: 36 | W43: =V43/G43 -> 0.8 | X43: 95.98 | Y43: =(X43/P43) -> 0.15455717 | AA43: =H43 -> 1440 | AB43: =N43 -> 1204.8639 | AC43: =P43 -> 621 | AD43: =U43 -> 540 | AE43: =AA43+AC43 -> 2061 | AF43: =AB43+AD43 -> 1744.8639
B44: TOTAL | D44: =AVERAGE(D13:D43) -> 238 | E44: =SUM(E13:E43) -> 411 | F44: =SUM(F13:F43) -> 24506 | G44: =SUM(G13:G43) -> 3809 | H44: =SUM(H13:H43) -> 128578 | I44: =H44/G44 -> 33.756367 | J44: =(G44/F44) -> 0.15543132 | K44: =SUM(K13:K43) -> 16771.043 | L44: =SUM(L13:L43) -> 111806.96 | M44: =SUM(M13:M43) -> 4464.78 | N44: =SUM(N13:N43) -> 107342.18 | P44: =SUM(P13:P43) -> 68528 | Q44: =P44/G44 -> 17.991074 | R44: =SUM(R13:R43) -> 1544 | S44: =(R44/G44) -> 0.40535574 | T44: =SUM(T13:T43) -> 8938.4348 | U44: =SUM(U13:U43) -> 59589.565 | V44: =SUM(V13:V43) -> 3553 | W44: =V44/G44 -> 0.93279076 | X44: =SUM(X13:X43) -> 12381.8 | Y44: =(X44/P44) -> 0.18068235 | AA44: =SUM(AA13:AA43) -> 128578 | AB44: =SUM(AB13:AB43) -> 107342.18 | AC44: =SUM(AC13:AC43) -> 68528 | AD44: =SUM(AD13:AD43) -> 59589.565 | AE44: =SUM(AE13:AE43) -> 197106 | AF44: =SUM(AF13:AF43) -> 166931.74

Sheet Apr2026
B2: NOIR Cinemas - Unaizah
B3: Managed & Operated by - Mukta A2 Cinemas
B5: Cinema | D5: Noir Cinema | G5: Month | I5: 46113
B6: Location | D6: Unizah | G6: Financial Year | I6: 2026
B7: Screens | D7: 4 | G7: VAT | I7: 0.15
B8: Seats | D8: 238 | G8: GCAM | I8: 0.1
G10: Box Office | P10: Concession | AA10: Total Box Office Revenue | AC10: Total Concession Revenue | AE10: Grand Total Revenue
B11: Date | C11: Day | D11: Seats | E11: Total Shows | F11: Total Available Capacity | G11: Admits | H11: Box Office Revenue | I11: ATP | J11: Occ % | K11: VAT (15%) | L11: Net BO Rev Before GCAM | M11: GCAM | N11: Net BO Rev After GCAM | P11: Concession Rev | Q11: SPH | R11: Transaction | S11: ASR | T11: VAT | U11: Net Concession Revenue | V11: Items Sold | W11: Concession Conversion % | X11: Concessions Standard Cost | Y11: COGS | AA11: Gross | AB11: Nett | AC11: Gross | AD11: Nett | AE11: Gross | AF11: Nett
B12: TOTAL MTD | D12: =D44 -> 238 | E12: =E44 -> 582 | F12: =F44 -> 34619 | G12: =G44 -> 3689 | H12: =H44 -> 123506.8 | I12: =I44 -> 33.479751 | J12: =J44 -> 0.10655998 | K12: =K44 -> 16109.583 | ... N12: =N44 -> 100374.97 | P12: =P44 -> 50049.53 | Q12: =Q44 -> 13.567235 | R12: =R44 -> 1187 | S12: =S44 -> 0.32176742 | T12: =T44 -> 6528.1996 | U12: =U44 -> 43521.33 | V12: =V44 -> 2611 | W12: =W44 -> 0.70777989 | ... Y12: =Y44 -> 0.17203418 | AA12: =AA44 -> 123506.8 | AB12: =AB44 -> 100374.97 | AC12: =AC44 -> 50049.53 | AD12: =AD44 -> 43521.33 | AE12: =AE44 -> 173556.33 | AF12: =AF44 -> 143896.3
B13: 46113 | C13: Wednesday | D13: 238 | E13: 17 | F13: 1012 | G13: 120 | H13: 4060 | I13: =H13/G13 -> 33.833333 | J13: =G13/F13 -> 0.11857708 | K13: =H13*15/115 -> 529.56522 | L13: =H13-K13 -> 3530.4348 | M13: 116.88 | N13: =L13-M13 -> 3413.5548 | P13: 2137 | Q13: =P13/G13 -> 17.808333 | R13: 40 | S13: =(R13/G13) -> 0.33333333 | T13: =P13*15/115 -> 278.73913 | U13: =P13-T13 -> 1858.2609 | V13: 119 | W13: =V13/G13 -> 0.99166667 | X13: 381.06 | Y13: =(X13/P13) -> 0.1783154 | AA13: =H13 -> 4060 | AB13: =N13 -> 3413.5548 | AC13: =P13 -> 2137 | AD13: =U13 -> 1858.2609 | AE13: =AA13+AC13 -> 6197 | AF13: =AB13+AD13 -> 5271.8157
B14: 46114 | C14: Thursday | D14: 238 | E14: 21 | F14: 1234 | G14: 294 | H14: 9748 | I14: =H14/G14 -> 33.156463 | J14: =G14/F14 -> 0.23824959 | K14: =H14*15/115 -> 1271.4783 | L14: =H14-K14 -> 8476.5217 | M14: 351.34 | N14: =L14-M14 -> 8125.1817 | P14: 3480 | Q14: =P14/G14 -> 11.836735 | R14: 76 | S14: =(R14/G14) -> 0.2585034 | T14: =P14*15/115 -> 453.91304 | U14: =P14-T14 -> 3026.087 | V14: 176 | W14: =V14/G14 -> 0.59863946 | X14: 547.89 | Y14: =(X14/P14) -> 0.15743966 | AA14: =H14 -> 9748 | AB14: =N14 -> 8125.1817 | AC14: =P14 -> 3480 | AD14: =U14 -> 3026.087 | AE14: =AA14+AC14 -> 13228 | AF14: =AB14+AD14 -> 11151.269
B15: 46115 | C15: Friday | D15: 238 | E15: 22 | F15: 1298 | G15: 445 | H15: 14870 | I15: =H15/G15 -> 33.41573 | J15: =G15/F15 -> 0.34283513 | K15: =H15*15/115 -> 1939.5652 | L15: =H15-K15 -> 12930.435 | M15: 670.51 | N15: =L15-M15 -> 12259.925 | P15: 6259 | Q15: =P15/G15 -> 14.065169 | R15: 107 | S15: =(R15/G15) -> 0.24044944 | T15: =P15*15/115 -> 816.3913 | U15: =P15-T15 -> 5442.6087 | V15: 317 | W15: =V15/G15 -> 0.71235955 | X15: 1018.33 | Y15: =(X15/P15) -> 0.16269851 | AA15: =H15 -> 14870 | AB15: =N15 -> 12259.925 | AC15: =P15 -> 6259 | AD15: =U15 -> 5442.6087 | AE15: =AA15+AC15 -> 21129 | AF15: =AB15+AD15 -> 17702.533
B16: 46116 | C16: Saturday | D16: 238 | E16: 25 | F16: 1472 | G16: 253 | H16: 8516 | I16: =H16/G16 -> 33.660079 | J16: =G16/F16 -> 0.171875 | K16: =H16*15/115 -> 1110.7826 | L16: =H16-K16 -> 7405.2174 | M16: 501.7 | N16: =L16-M16 -> 6903.5174 | P16: 3268 | Q16: =P16/G16 -> 12.916996 | R16: 77 | S16: =(R16/G16) -> 0.30434783 | T16: =P16*15/115 -> 426.26087 | U16: =P16-T16 -> 2841.7391 | V16: 161 | W16: =V16/G16 -> 0.63636364 | X16: 552.6 | Y16: =(X16/P16) -> 0.16909425 | AA16: =H16 -> 8516 | AB16: =N16 -> 6903.5174 | AC16: =P16 -> 3268 | AD16: =U16 -> 2841.7391 | AE16: =AA16+AC16 -> 11784 | AF16: =AB16+AD16 -> 9745.2565
B17: 46117 | C17: Sunday | D17: 238 | E17: 19 | F17: 1133 | G17: 171 | H17: 5702 | I17: =H17/G17 -> 33.345029 | J17: =G17/F17 -> 0.15092674 | K17: =H17*15/115 -> 743.73913 | L17: =H17-K17 -> 4958.2609 | M17: 426.31 | N17: =L17-M17 -> 4531.9509 | P17: 1368.93 | Q17: =P17/G17 -> 8.0054386 | R17: 40 | S17: =(R17/G17) -> 0.23391813 | T17: =P17*15/115 -> 178.55609 | U17: =P17-T17 -> 1190.3739 | V17: 78 | W17: =V17/G17 -> 0.45614035 | X17: 279.73 | Y17: =(X17/P17) -> 0.20434208 | AA17: =H17 -> 5702 | AB17: =N17 -> 4531.9509 | AC17: =P17 -> 1368.93 | AD17: =U17 -> 1190.3739 | AE17: =AA17+AC17 -> 7070.93 | AF17: =AB17+AD17 -> 5722.3248
B18: 46118 | C18: Monday | D18: 238 | E18: 20 | F18: 1197 | G18: 186 | H18: 6212 | I18: =H18/G18 -> 33.397849 | J18: =G18/F18 -> 0.15538847 | K18: =H18*15/115 -> 810.26087 | L18: =H18-K18 -> 5401.7391 | M18: 515.19 | N18: =L18-M18 -> 4886.5491 | P18: 1347 | Q18: =P18/G18 -> 7.2419355 | R18: 44 | S18: =(R18/G18) -> 0.23655914 | T18: =P18*15/115 -> 175.69565 | U18: =P18-T18 -> 1171.3043 | V18: 69 | W18: =V18/G18 -> 0.37096774 | X18: 239.67 | Y18: =(X18/P18) -> 0.17792873 | AA18: =H18 -> 6212 | AB18: =N18 -> 4886.5491 | AC18: =P18 -> 1347 | AD18: =U18 -> 1171.3043 | AE18: =AA18+AC18 -> 7559 | AF18: =AB18+AD18 -> 6057.8535
B19: 46119 | C19: Tuesday | D19: 238 | E19: 19 | F19: 1133 | G19: 145 | H19: 4820 | I19: =H19/G19 -> 33.241379 | J19: =G19/F19 -> 0.12797882 | K19: =H19*15/115 -> 628.69565 | L19: =H19-K19 -> 4191.3043 | M19: 330.12 | N19: =L19-M19 -> 3861.1843 | P19: 1764 | Q19: =P19/G19 -> 12.165517 | R19: 44 | S19: =(R19/G19) -> 0.30344828 | T19: =P19*15/115 -> 230.08696 | U19: =P19-T19 -> 1533.913 | V19: 86 | W19: =V19/G19 -> 0.59310345 | X19: 269.27 | Y19: =(X19/P19) -> 0.15264739 | AA19: =H19 -> 4820 | AB19: =N19 -> 3861.1843 | AC19: =P19 -> 1764 | AD19: =U19 -> 1533.913 | AE19: =AA19+AC19 -> 6584 | AF19: =AB19+AD19 -> 5395.0974
B20: 46120 | C20: Wednesday | D20: 238 | E20: 19 | F20: 1133 | G20: 130 | H20: 4360 | I20: =H20/G20 -> 33.538462 | J20: =G20/F20 -> 0.11473963 | K20: =H20*15/115 -> 568.69565 | L20: =H20-K20 -> 3791.3043 | M20: 323.51 | N20: =L20-M20 -> 3467.7943 | P20: 1452 | Q20: =P20/G20 -> 11.169231 | R20: 37 | S20: =(R20/G20) -> 0.28461538 | T20: =P20*15/115 -> 189.3913 | U20: =P20-T20 -> 1262.6087 | V20: 77 | W20: =V20/G20 -> 0.59230769 | X20: 273.94 | Y20: =(X20/P20) -> 0.18866391 | AA20: =H20 -> 4360 | AB20: =N20 -> 3467.7943 | AC20: =P20 -> 1452 | AD20: =U20 -> 1262.6087 | AE20: =AA20+AC20 -> 5812 | AF20: =AB20+AD20 -> 4730.403
B21: 46121 | C21: Thursday | D21: 238 | E21: 20 | F21: 1170 | G21: 306 | H21: 10342 | I21: =H21/G21 -> 33.797386 | J21: =G21/F21 -> 0.26153846 | K21: =H21*15/115 -> 1348.9565 | L21: =H21-K21 -> 8993.0435 | M21: 586.66 | N21: =L21-M21 -> 8406.3835 | P21: 3742 | Q21: =P21/G21 -> 12.228758 | R21: 86 | S21: =(R21/G21) -> 0.28104575 | T21: =P21*15/115 -> 488.08696 | U21: =P21-T21 -> 3253.913 | V21: 191 | W21: =V21/G21 -> 0.62418301 | X21: 661.68 | Y21: =(X21/P21) -> 0.17682523 | AA21: =H21 -> 10342 | AB21: =N21 -> 8406.3835 | AC21: =P21 -> 3742 | AD21: =U21 -> 3253.913 | AE21: =AA21+AC21 -> 14084 | AF21: =AB21+AD21 -> 11660.297
B22: 46122 | C22: Friday | D22: 238 | E22: 19 | F22: 1106 | G22: 437 | H22: 14654 | I22: =H22/G22 -> 33.533181 | J22: =G22/F22 -> 0.39511754 | K22: =H22*15/115 -> 1911.3913 | L22: =H22-K22 -> 12742.609 | M22: 823.56 | N22: =L22-M22 -> 11919.049 | P22: 4449 | Q22: =P22/G22 -> 10.180778 | R22: 118 | S22: =(R22/G22) -> 0.27002288 | T22: =P22*15/115 -> 580.30435 | U22: =P22-T22 -> 3868.6957 | V22: 224 | W22: =V22/G22 -> 0.51258581 | X22: 758 | Y22: =(X22/P22) -> 0.17037537 | AA22: =H22 -> 14654 | AB22: =N22 -> 11919.049 | AC22: =P22 -> 4449 | AD22: =U22 -> 3868.6957 | AE22: =AA22+AC22 -> 19103 | AF22: =AB22+AD22 -> 15787.744
B23: 46123 | C23: Saturday | D23: 238 | E23: 22 | F23: 1280 | G23: 159 | H23: 5358 | I23: =H23/G23 -> 33.698113 | J23: =G23/F23 -> 0.12421875 | K23: =H23*15/115 -> 698.86957 | L23: =H23-K23 -> 4659.1304 | M23: 275.33 | N23: =L23-M23 -> 4383.8004 | P23: 3275 | Q23: =P23/G23 -> 20.597484 | R23: 60 | S23: =(R23/G23) -> 0.37735849 | T23: =P23*15/115 -> 427.17391 | U23: =P23-T23 -> 2847.8261 | V23: 155 | W23: =V23/G23 -> 0.97484277 | X23: 526.54 | Y23: =(X23/P23) -> 0.16077557 | AA23: =H23 -> 5358 | AB23: =N23 -> 4383.8004 | AC23: =P23 -> 3275 | AD23: =U23 -> 2847.8261 | AE23: =AA23+AC23 -> 8633 | AF23: =AB23+AD23 -> 7231.6265
B24: 46124 | C24: Sunday | D24: 238 | E24: 19 | F24: 1106 | G24: 35 | H24: 1200 | I24: =H24/G24 -> 34.285714 | J24: =G24/F24 -> 0.03164557 | K24: =H24*15/115 -> 156.52174 | L24: =H24-K24 -> 1043.4783 | M24: 79.31 | N24: =L24-M24 -> 964.16826 | P24: 753 | Q24: =P24/G24 -> 21.514286 | R24: 24 | S24: =(R24/G24) -> 0.68571429 | T24: =P24*15/115 -> 98.217391 | U24: =P24-T24 -> 654.78261 | V24: 38 | W24: =V24/G24 -> 1.0857143 | X24: 116.66 | Y24: =(X24/P24) -> 0.15492696 | AA24: =H24 -> 1200 | AB24: =N24 -> 964.16826 | AC24: =P24 -> 753 | AD24: =U24 -> 654.78261 | AE24: =AA24+AC24 -> 1953 | AF24: =AB24+AD24 -> 1618.9509
... B43: 46112 | C43: Tuesday | D43: 238 | E43: 0 | F43: 0 | G43: 0 | H43: 0 | I43: =H43/G43 -> #DIV/0! | J43: =G43/F43 -> #DIV/0! | K43: =H43*15/115 -> 0 | L43: =H43-K43 -> 0 | M43: 0 | N43: =L43-M43 -> 0 | P43: 0 | Q43: =P43/G43 -> #DIV/0! | R43: 0 | S43: =(R43/G43) -> #DIV/0! | T43: =P43*15/115 -> 0 | U43: =P43-T43 -> 0 | V43: 0 | W43: =V43/G43 -> #DIV/0! | X43: 0 | Y43: =(X43/P43) -> #DIV/0! | AA43: =H43 -> 0 | AB43: =N43 -> 0 | AC43: =P43 -> 0 | AD43: =U43 -> 0 | AE43: =AA43+AC43 -> 0 | AF43: =AB43+AD43 -> 0
B44: TOTAL | D44: =AVERAGE(D13:D43) -> 238 | E44: =SUM(E13:E43) -> 582 | F44: =SUM(F13:F43) -> 34619 | G44: =SUM(G13:G43) -> 3689 | H44: =SUM(H13:H43) -> 123506.8 | I44: =H44/G44 -> 33.479751 | J44: =(G44/F44) -> 0.10655998 | K44: =SUM(K13:K43) -> 16109.583 | L44: =SUM(L13:L43) -> 107397.22 | M44: =SUM(M13:M43) -> 7022.25 | N44: =SUM(N13:N43) -> 100374.97 | P44: =SUM(P13:P43) -> 50049.53 | Q44: =P44/G44 -> 13.567235 | R44: =SUM(R13:R43) -> 1187 | S44: =(R44/G44) -> 0.32176742 | T44: =SUM(T13:T43) -> 6528.1996 | U44: =SUM(U13:U43) -> 43521.33 | V44: =SUM(V13:V43) -> 2611 | W44: =V44/G44 -> 0.70777989 | X44: =SUM(X13:X43) -> 8610.23 | Y44: =(X44/P44) -> 0.17203418 | AA44: =SUM(AA13:AA43) -> 123506.8 | AB44: =SUM(AB13:AB43) -> 100374.97 | AC44: =SUM(AC13:AC43) -> 50049.53 | AD44: =SUM(AD13:AD43) -> 43521.33 | AE44: =SUM(AE13:AE43) -> 173556.33 | AF44: =SUM(AF13:AF43) -> 143896.3

Sheet May 2026
B2: NOIR Cinemas - Unaizah
B3: Managed & Operated by - Mukta A2 Cinemas
B5: Cinema | D5: Noir Cinema | G5: Month | I5: 46143
B6: Location | D6: Unizah | G6: Financial Year | I6: 2026
B7: Screens | D7: 4 | G7: VAT | I7: 0.15
B8: Seats | D8: 238 | G8: GCAM | I8: 0.1
G10: Box Office | P10: Concession | AA10: Total Box Office Revenue | AC10: Total Concession Revenue | AE10: Grand Total Revenue
B11: Date | C11: Day | D11: Seats | E11: Total Shows | F11: Total Available Capacity | G11: Admits | H11: Box Office Revenue | I11: ATP | J11: Occ % | K11: VAT (15%) | L11: Net BO Rev Before GCAM | M11: GCAM | N11: Net BO Rev After GCAM | P11: Concession Rev | Q11: SPH | R11: Transaction | S11: ASR | T11: VAT | U11: Net Concession Revenue | V11: Items Sold | W11: Concession Conversion % | X11: Concessions Standard Cost | Y11: COGS | AA11: Gross | AB11: Nett | AC11: Gross | AD11: Nett | AE11: Gross | AF11: Nett
B12: TOTAL MTD | D12: =D44 -> 238 | E12: =E44 -> 551 | F12: =F44 -> 32481 | G12: =G44 -> 4122 | H12: =H44 -> 137751.18 | I12: =I44 -> 33.41853 | J12: =J44 -> 0.12690496 | K12: =K44 -> 17967.545 | ... N12: =N44 -> 110092.17 | P12: =P44 -> 53778.71 | Q12: =Q44 -> 13.046752 | R12: =R44 -> 1375 | S12: =S44 -> 0.33357593 | T12: =T44 -> 7014.6143 | U12: =U44 -> 46764.096 | V12: =V44 -> 2627 | W12: =W44 -> 0.63731198 | ... Y12: =Y44 -> 0.19948452 | AA12: =AA44 -> 137751.18 | AB12: =AB44 -> 110092.17 | AC12: =AC44 -> 53778.71 | AD12: =AD44 -> 46764.096 | AE12: =AE44 -> 191529.89 | AF12: =AF44 -> 156856.27
